[2024-10-13T21:12:12.851+0000] {taskinstance.py:1090} INFO - Dependencies all met for dep_context=non-requeueable deps ti=<TaskInstance: pipeline_Test_2.S3_to_DB manual__2024-10-13T21:11:51.236979+00:00 [queued]>
[2024-10-13T21:12:12.856+0000] {taskinstance.py:1090} INFO - Dependencies all met for dep_context=requeueable deps ti=<TaskInstance: pipeline_Test_2.S3_to_DB manual__2024-10-13T21:11:51.236979+00:00 [queued]>
[2024-10-13T21:12:12.856+0000] {taskinstance.py:1288} INFO - 
--------------------------------------------------------------------------------
[2024-10-13T21:12:12.856+0000] {taskinstance.py:1289} INFO - Starting attempt 1 of 1
[2024-10-13T21:12:12.856+0000] {taskinstance.py:1290} INFO - 
--------------------------------------------------------------------------------
[2024-10-13T21:12:12.860+0000] {taskinstance.py:1309} INFO - Executing <Task(PythonOperator): S3_to_DB> on 2024-10-13 21:11:51.236979+00:00
[2024-10-13T21:12:12.865+0000] {standard_task_runner.py:55} INFO - Started process 721 to run task
[2024-10-13T21:12:12.867+0000] {standard_task_runner.py:82} INFO - Running: ['***', 'tasks', 'run', 'pipeline_Test_2', 'S3_to_DB', 'manual__2024-10-13T21:11:51.236979+00:00', '--job-id', '6', '--raw', '--subdir', 'DAGS_FOLDER/pipeline_Test_2.py', '--cfg-path', '/tmp/tmp2ixjbk08']
[2024-10-13T21:12:12.868+0000] {standard_task_runner.py:83} INFO - Job 6: Subtask S3_to_DB
[2024-10-13T21:12:12.877+0000] {logging_mixin.py:137} WARNING - /usr/local/lib/python3.9/site-packages/***/settings.py:250 DeprecationWarning: The sql_alchemy_conn option in [core] has been moved to the sql_alchemy_conn option in [database] - the old setting has been used, but please update your config.
[2024-10-13T21:12:12.909+0000] {task_command.py:389} INFO - Running <TaskInstance: pipeline_Test_2.S3_to_DB manual__2024-10-13T21:11:51.236979+00:00 [running]> on host 764f93acab86
[2024-10-13T21:12:12.943+0000] {taskinstance.py:1516} INFO - Exporting the following env vars:
AIRFLOW_CTX_DAG_OWNER=***
AIRFLOW_CTX_DAG_ID=pipeline_Test_2
AIRFLOW_CTX_TASK_ID=S3_to_DB
AIRFLOW_CTX_EXECUTION_DATE=2024-10-13T21:11:51.236979+00:00
AIRFLOW_CTX_TRY_NUMBER=1
AIRFLOW_CTX_DAG_RUN_ID=manual__2024-10-13T21:11:51.236979+00:00
[2024-10-13T21:12:12.944+0000] {taskinstance.py:1776} ERROR - Task failed with exception
Traceback (most recent call last):
  File "/usr/local/lib/python3.9/site-packages/airflow/operators/python.py", line 175, in execute
    return_value = self.execute_callable()
  File "/usr/local/lib/python3.9/site-packages/airflow/operators/python.py", line 192, in execute_callable
    return self.python_callable(*self.op_args, **self.op_kwargs)
  File "/opt/airflow/scripts/s3_db.py", line 289, in main_s3_db
    s3_conn['s3_access_key'] = secret_vals[s3_access]['s3_access_key']
KeyError: 's3_access'
[2024-10-13T21:12:12.950+0000] {taskinstance.py:1327} INFO - Marking task as FAILED. dag_id=pipeline_Test_2, task_id=S3_to_DB, execution_date=20241013T211151, start_date=20241013T211212, end_date=20241013T211212
[2024-10-13T21:12:12.959+0000] {standard_task_runner.py:100} ERROR - Failed to execute job 6 for task S3_to_DB ('s3_access'; 721)
[2024-10-13T21:12:13.007+0000] {local_task_job.py:212} INFO - Task exited with return code 1
[2024-10-13T21:12:13.020+0000] {taskinstance.py:2596} INFO - 0 downstream tasks scheduled from follow-on schedule check
