[2024-10-10T21:52:33.201+0000] {taskinstance.py:1090} INFO - Dependencies all met for dep_context=non-requeueable deps ti=<TaskInstance: pipeline_s3_db_test_1.task_0_S3_to_DB manual__2024-10-10T21:52:29.218175+00:00 [queued]>
[2024-10-10T21:52:33.207+0000] {taskinstance.py:1090} INFO - Dependencies all met for dep_context=requeueable deps ti=<TaskInstance: pipeline_s3_db_test_1.task_0_S3_to_DB manual__2024-10-10T21:52:29.218175+00:00 [queued]>
[2024-10-10T21:52:33.207+0000] {taskinstance.py:1288} INFO - 
--------------------------------------------------------------------------------
[2024-10-10T21:52:33.207+0000] {taskinstance.py:1289} INFO - Starting attempt 1 of 1
[2024-10-10T21:52:33.207+0000] {taskinstance.py:1290} INFO - 
--------------------------------------------------------------------------------
[2024-10-10T21:52:33.212+0000] {taskinstance.py:1309} INFO - Executing <Task(PythonOperator): task_0_S3_to_DB> on 2024-10-10 21:52:29.218175+00:00
[2024-10-10T21:52:33.219+0000] {standard_task_runner.py:55} INFO - Started process 4923 to run task
[2024-10-10T21:52:33.232+0000] {standard_task_runner.py:82} INFO - Running: ['***', 'tasks', 'run', 'pipeline_s3_db_test_1', 'task_0_S3_to_DB', 'manual__2024-10-10T21:52:29.218175+00:00', '--job-id', '23', '--raw', '--subdir', 'DAGS_FOLDER/pipeline_s3_db_test_1.py', '--cfg-path', '/tmp/tmp7zowi4y8']
[2024-10-10T21:52:33.235+0000] {standard_task_runner.py:83} INFO - Job 23: Subtask task_0_S3_to_DB
[2024-10-10T21:52:33.257+0000] {logging_mixin.py:137} WARNING - /usr/local/lib/python3.9/site-packages/***/settings.py:250 DeprecationWarning: The sql_alchemy_conn option in [core] has been moved to the sql_alchemy_conn option in [database] - the old setting has been used, but please update your config.
[2024-10-10T21:52:33.323+0000] {task_command.py:389} INFO - Running <TaskInstance: pipeline_s3_db_test_1.task_0_S3_to_DB manual__2024-10-10T21:52:29.218175+00:00 [running]> on host d6685a94b59c
[2024-10-10T21:52:33.506+0000] {taskinstance.py:1516} INFO - Exporting the following env vars:
AIRFLOW_CTX_DAG_OWNER=***
AIRFLOW_CTX_DAG_ID=pipeline_s3_db_test_1
AIRFLOW_CTX_TASK_ID=task_0_S3_to_DB
AIRFLOW_CTX_EXECUTION_DATE=2024-10-10T21:52:29.218175+00:00
AIRFLOW_CTX_TRY_NUMBER=1
AIRFLOW_CTX_DAG_RUN_ID=manual__2024-10-10T21:52:29.218175+00:00
[2024-10-10T21:52:33.510+0000] {s3_db.py:130} INFO - Executing S3 File read.......
[2024-10-10T21:52:33.511+0000] {s3_db.py:17} INFO - Creating Spark session ......
[2024-10-10T21:52:42.018+0000] {s3_db.py:72} INFO - Executing File pattern check......
[2024-10-10T21:52:42.692+0000] {s3_db.py:117} INFO - Latest file for pattern - sftp_\d{8}\.txt at s3a://sdevalla-buck/test: sftp_20241011.txt
[2024-10-10T21:52:44.066+0000] {taskinstance.py:1776} ERROR - Task failed with exception
Traceback (most recent call last):
  File "/usr/local/lib/python3.9/site-packages/airflow/operators/python.py", line 175, in execute
    return_value = self.execute_callable()
  File "/usr/local/lib/python3.9/site-packages/airflow/operators/python.py", line 192, in execute_callable
    return self.python_callable(*self.op_args, **self.op_kwargs)
  File "/opt/airflow/scripts/s3_db.py", line 307, in main_s3_db
    inputs = s3_file_read(s3_conn, source_s3_path, header, delimiter, s3_access, db_access,target_table, run_id, dag_id)
  File "/opt/airflow/scripts/s3_db.py", line 169, in s3_file_read
    df = spark.read.option("inferSchema", "true").option("header", header).option("delimiter",delimiter).csv(file_path)
  File "/usr/local/lib/python3.9/site-packages/pyspark/sql/readwriter.py", line 727, in csv
    return self._df(self._jreader.csv(self._spark._sc._jvm.PythonUtils.toSeq(path)))
  File "/usr/local/lib/python3.9/site-packages/py4j/java_gateway.py", line 1322, in __call__
    return_value = get_return_value(
  File "/usr/local/lib/python3.9/site-packages/pyspark/errors/exceptions/captured.py", line 175, in deco
    raise converted from None
pyspark.errors.exceptions.captured.AnalysisException: [PATH_NOT_FOUND] Path does not exist: s3a://sdevalla-buck/test/sftp_20241011.txt.
[2024-10-10T21:52:44.102+0000] {taskinstance.py:1327} INFO - Marking task as FAILED. dag_id=pipeline_s3_db_test_1, task_id=task_0_S3_to_DB, execution_date=20241010T215229, start_date=20241010T215233, end_date=20241010T215244
[2024-10-10T21:52:44.123+0000] {standard_task_runner.py:100} ERROR - Failed to execute job 23 for task task_0_S3_to_DB ([PATH_NOT_FOUND] Path does not exist: s3a://sdevalla-buck/test/sftp_20241011.txt.; 4923)
[2024-10-10T21:52:44.166+0000] {local_task_job.py:212} INFO - Task exited with return code 1
[2024-10-10T21:52:44.203+0000] {taskinstance.py:2596} INFO - 0 downstream tasks scheduled from follow-on schedule check
