[2024-10-13T19:06:23.159+0000] {taskinstance.py:1090} INFO - Dependencies all met for dep_context=non-requeueable deps ti=<TaskInstance: pipeline_Demo.S3_to_DB manual__2024-10-13T19:05:43.044427+00:00 [queued]>
[2024-10-13T19:06:23.163+0000] {taskinstance.py:1090} INFO - Dependencies all met for dep_context=requeueable deps ti=<TaskInstance: pipeline_Demo.S3_to_DB manual__2024-10-13T19:05:43.044427+00:00 [queued]>
[2024-10-13T19:06:23.164+0000] {taskinstance.py:1288} INFO - 
--------------------------------------------------------------------------------
[2024-10-13T19:06:23.164+0000] {taskinstance.py:1289} INFO - Starting attempt 1 of 1
[2024-10-13T19:06:23.164+0000] {taskinstance.py:1290} INFO - 
--------------------------------------------------------------------------------
[2024-10-13T19:06:23.169+0000] {taskinstance.py:1309} INFO - Executing <Task(PythonOperator): S3_to_DB> on 2024-10-13 19:05:43.044427+00:00
[2024-10-13T19:06:23.174+0000] {standard_task_runner.py:55} INFO - Started process 1196 to run task
[2024-10-13T19:06:23.176+0000] {standard_task_runner.py:82} INFO - Running: ['***', 'tasks', 'run', 'pipeline_Demo', 'S3_to_DB', 'manual__2024-10-13T19:05:43.044427+00:00', '--job-id', '7', '--raw', '--subdir', 'DAGS_FOLDER/pipeline_Demo.py', '--cfg-path', '/tmp/tmpbze7q3k6']
[2024-10-13T19:06:23.178+0000] {standard_task_runner.py:83} INFO - Job 7: Subtask S3_to_DB
[2024-10-13T19:06:23.186+0000] {logging_mixin.py:137} WARNING - /usr/local/lib/python3.9/site-packages/***/settings.py:250 DeprecationWarning: The sql_alchemy_conn option in [core] has been moved to the sql_alchemy_conn option in [database] - the old setting has been used, but please update your config.
[2024-10-13T19:06:23.208+0000] {task_command.py:389} INFO - Running <TaskInstance: pipeline_Demo.S3_to_DB manual__2024-10-13T19:05:43.044427+00:00 [running]> on host c3a571b96d5f
[2024-10-13T19:06:23.234+0000] {taskinstance.py:1516} INFO - Exporting the following env vars:
AIRFLOW_CTX_DAG_OWNER=***
AIRFLOW_CTX_DAG_ID=pipeline_Demo
AIRFLOW_CTX_TASK_ID=S3_to_DB
AIRFLOW_CTX_EXECUTION_DATE=2024-10-13T19:05:43.044427+00:00
AIRFLOW_CTX_TRY_NUMBER=1
AIRFLOW_CTX_DAG_RUN_ID=manual__2024-10-13T19:05:43.044427+00:00
[2024-10-13T19:06:23.238+0000] {s3_db.py:129} INFO - Executing S3 File read.......
[2024-10-13T19:06:23.238+0000] {s3_db.py:16} INFO - Creating Spark session ......
[2024-10-13T19:06:25.928+0000] {s3_db.py:71} INFO - Executing File pattern check......
[2024-10-13T19:06:25.928+0000] {logging_mixin.py:137} INFO - prefix: sftp_file_receiver
[2024-10-13T19:06:26.415+0000] {s3_db.py:116} INFO - Latest file for pattern - sftp_s3_\d{14}\.csv at s3a://sdevalla-buck/sftp_file_receiver: sftp_s3_20241013190610.csv
[2024-10-13T19:06:29.966+0000] {s3_db.py:51} INFO - Updating run log for read operation....
[2024-10-13T19:06:29.968+0000] {s3_db.py:55} INFO - Run log updated successfully....
[2024-10-13T19:06:29.971+0000] {s3_db.py:238} INFO - Executing file writing function .....
[2024-10-13T19:06:30.214+0000] {logging_mixin.py:137} WARNING - --- Logging error ---
[2024-10-13T19:06:30.218+0000] {logging_mixin.py:137} WARNING - Traceback (most recent call last):
[2024-10-13T19:06:30.218+0000] {logging_mixin.py:137} WARNING -   File "/usr/local/lib/python3.9/logging/__init__.py", line 1083, in emit
    msg = self.format(record)
[2024-10-13T19:06:30.218+0000] {logging_mixin.py:137} WARNING -   File "/usr/local/lib/python3.9/logging/__init__.py", line 927, in format
    return fmt.format(record)
[2024-10-13T19:06:30.219+0000] {logging_mixin.py:137} WARNING -   File "/usr/local/lib/python3.9/logging/__init__.py", line 663, in format
    record.message = record.getMessage()
[2024-10-13T19:06:30.219+0000] {logging_mixin.py:137} WARNING -   File "/usr/local/lib/python3.9/logging/__init__.py", line 367, in getMessage
    msg = msg % self.args
[2024-10-13T19:06:30.219+0000] {logging_mixin.py:137} WARNING - TypeError: not all arguments converted during string formatting
[2024-10-13T19:06:30.219+0000] {logging_mixin.py:137} WARNING - Call stack:
[2024-10-13T19:06:30.224+0000] {logging_mixin.py:137} WARNING -   File "/usr/local/bin/***", line 8, in <module>
    sys.exit(main())
[2024-10-13T19:06:30.224+0000] {logging_mixin.py:137} WARNING -   File "/usr/local/lib/python3.9/site-packages/***/__main__.py", line 48, in main
    args.func(args)
[2024-10-13T19:06:30.225+0000] {logging_mixin.py:137} WARNING -   File "/usr/local/lib/python3.9/site-packages/***/cli/cli_parser.py", line 52, in command
    return func(*args, **kwargs)
[2024-10-13T19:06:30.225+0000] {logging_mixin.py:137} WARNING -   File "/usr/local/lib/python3.9/site-packages/***/utils/cli.py", line 108, in wrapper
    return f(*args, **kwargs)
[2024-10-13T19:06:30.225+0000] {logging_mixin.py:137} WARNING -   File "/usr/local/lib/python3.9/site-packages/***/cli/commands/scheduler_command.py", line 73, in scheduler
    _run_scheduler_job(args=args)
[2024-10-13T19:06:30.225+0000] {logging_mixin.py:137} WARNING -   File "/usr/local/lib/python3.9/site-packages/***/cli/commands/scheduler_command.py", line 43, in _run_scheduler_job
    job.run()
[2024-10-13T19:06:30.225+0000] {logging_mixin.py:137} WARNING -   File "/usr/local/lib/python3.9/site-packages/***/jobs/base_job.py", line 258, in run
    self._execute()
[2024-10-13T19:06:30.225+0000] {logging_mixin.py:137} WARNING -   File "/usr/local/lib/python3.9/site-packages/***/jobs/scheduler_job.py", line 750, in _execute
    self.executor.start()
[2024-10-13T19:06:30.225+0000] {logging_mixin.py:137} WARNING -   File "/usr/local/lib/python3.9/site-packages/***/executors/local_executor.py", line 360, in start
    self.impl.start()
[2024-10-13T19:06:30.225+0000] {logging_mixin.py:137} WARNING -   File "/usr/local/lib/python3.9/site-packages/***/executors/local_executor.py", line 301, in start
    worker.start()
[2024-10-13T19:06:30.225+0000] {logging_mixin.py:137} WARNING -   File "/usr/local/lib/python3.9/multiprocessing/process.py", line 121, in start
    self._popen = self._Popen(self)
[2024-10-13T19:06:30.225+0000] {logging_mixin.py:137} WARNING -   File "/usr/local/lib/python3.9/multiprocessing/context.py", line 224, in _Popen
    return _default_context.get_context().Process._Popen(process_obj)
[2024-10-13T19:06:30.225+0000] {logging_mixin.py:137} WARNING -   File "/usr/local/lib/python3.9/multiprocessing/context.py", line 277, in _Popen
    return Popen(process_obj)
[2024-10-13T19:06:30.225+0000] {logging_mixin.py:137} WARNING -   File "/usr/local/lib/python3.9/multiprocessing/popen_fork.py", line 19, in __init__
    self._launch(process_obj)
[2024-10-13T19:06:30.225+0000] {logging_mixin.py:137} WARNING -   File "/usr/local/lib/python3.9/multiprocessing/popen_fork.py", line 71, in _launch
    code = process_obj._bootstrap(parent_sentinel=child_r)
[2024-10-13T19:06:30.225+0000] {logging_mixin.py:137} WARNING -   File "/usr/local/lib/python3.9/multiprocessing/process.py", line 315, in _bootstrap
    self.run()
[2024-10-13T19:06:30.225+0000] {logging_mixin.py:137} WARNING -   File "/usr/local/lib/python3.9/site-packages/***/executors/local_executor.py", line 69, in run
    return super().run()
[2024-10-13T19:06:30.225+0000] {logging_mixin.py:137} WARNING -   File "/usr/local/lib/python3.9/multiprocessing/process.py", line 108, in run
    self._target(*self._args, **self._kwargs)
[2024-10-13T19:06:30.225+0000] {logging_mixin.py:137} WARNING -   File "/usr/local/lib/python3.9/site-packages/***/executors/local_executor.py", line 192, in do_work
    self.execute_work(key=key, command=command)
[2024-10-13T19:06:30.226+0000] {logging_mixin.py:137} WARNING -   File "/usr/local/lib/python3.9/site-packages/***/executors/local_executor.py", line 86, in execute_work
    state = self._execute_work_in_fork(command)
[2024-10-13T19:06:30.226+0000] {logging_mixin.py:137} WARNING -   File "/usr/local/lib/python3.9/site-packages/***/executors/local_executor.py", line 126, in _execute_work_in_fork
    args.func(args)
[2024-10-13T19:06:30.226+0000] {logging_mixin.py:137} WARNING -   File "/usr/local/lib/python3.9/site-packages/***/cli/cli_parser.py", line 52, in command
    return func(*args, **kwargs)
[2024-10-13T19:06:30.226+0000] {logging_mixin.py:137} WARNING -   File "/usr/local/lib/python3.9/site-packages/***/utils/cli.py", line 108, in wrapper
    return f(*args, **kwargs)
[2024-10-13T19:06:30.226+0000] {logging_mixin.py:137} WARNING -   File "/usr/local/lib/python3.9/site-packages/***/cli/commands/task_command.py", line 396, in task_run
    _run_task_by_selected_method(args, dag, ti)
[2024-10-13T19:06:30.226+0000] {logging_mixin.py:137} WARNING -   File "/usr/local/lib/python3.9/site-packages/***/cli/commands/task_command.py", line 194, in _run_task_by_selected_method
    _run_task_by_local_task_job(args, ti)
[2024-10-13T19:06:30.226+0000] {logging_mixin.py:137} WARNING -   File "/usr/local/lib/python3.9/site-packages/***/cli/commands/task_command.py", line 253, in _run_task_by_local_task_job
    run_job.run()
[2024-10-13T19:06:30.226+0000] {logging_mixin.py:137} WARNING -   File "/usr/local/lib/python3.9/site-packages/***/jobs/base_job.py", line 258, in run
    self._execute()
[2024-10-13T19:06:30.226+0000] {logging_mixin.py:137} WARNING -   File "/usr/local/lib/python3.9/site-packages/***/jobs/local_task_job.py", line 155, in _execute
    self.task_runner.start()
[2024-10-13T19:06:30.226+0000] {logging_mixin.py:137} WARNING -   File "/usr/local/lib/python3.9/site-packages/***/task/task_runner/standard_task_runner.py", line 43, in start
    self.process = self._start_by_fork()
[2024-10-13T19:06:30.226+0000] {logging_mixin.py:137} WARNING -   File "/usr/local/lib/python3.9/site-packages/***/task/task_runner/standard_task_runner.py", line 95, in _start_by_fork
    args.func(args, dag=self.dag)
[2024-10-13T19:06:30.226+0000] {logging_mixin.py:137} WARNING -   File "/usr/local/lib/python3.9/site-packages/***/cli/cli_parser.py", line 52, in command
    return func(*args, **kwargs)
[2024-10-13T19:06:30.226+0000] {logging_mixin.py:137} WARNING -   File "/usr/local/lib/python3.9/site-packages/***/utils/cli.py", line 108, in wrapper
    return f(*args, **kwargs)
[2024-10-13T19:06:30.226+0000] {logging_mixin.py:137} WARNING -   File "/usr/local/lib/python3.9/site-packages/***/cli/commands/task_command.py", line 396, in task_run
    _run_task_by_selected_method(args, dag, ti)
[2024-10-13T19:06:30.226+0000] {logging_mixin.py:137} WARNING -   File "/usr/local/lib/python3.9/site-packages/***/cli/commands/task_command.py", line 196, in _run_task_by_selected_method
    _run_raw_task(args, ti)
[2024-10-13T19:06:30.226+0000] {logging_mixin.py:137} WARNING -   File "/usr/local/lib/python3.9/site-packages/***/cli/commands/task_command.py", line 270, in _run_raw_task
    ti._run_raw_task(
[2024-10-13T19:06:30.226+0000] {logging_mixin.py:137} WARNING -   File "/usr/local/lib/python3.9/site-packages/***/utils/session.py", line 75, in wrapper
    return func(*args, session=session, **kwargs)
[2024-10-13T19:06:30.226+0000] {logging_mixin.py:137} WARNING -   File "/usr/local/lib/python3.9/site-packages/***/models/taskinstance.py", line 1383, in _run_raw_task
    self._execute_task_with_callbacks(context, test_mode)
[2024-10-13T19:06:30.227+0000] {logging_mixin.py:137} WARNING -   File "/usr/local/lib/python3.9/site-packages/***/models/taskinstance.py", line 1529, in _execute_task_with_callbacks
    result = self._execute_task(context, task_orig)
[2024-10-13T19:06:30.227+0000] {logging_mixin.py:137} WARNING -   File "/usr/local/lib/python3.9/site-packages/***/models/taskinstance.py", line 1589, in _execute_task
    result = execute_callable(context=context)
[2024-10-13T19:06:30.227+0000] {logging_mixin.py:137} WARNING -   File "/usr/local/lib/python3.9/site-packages/***/operators/python.py", line 175, in execute
    return_value = self.execute_callable()
[2024-10-13T19:06:30.227+0000] {logging_mixin.py:137} WARNING -   File "/usr/local/lib/python3.9/site-packages/***/operators/python.py", line 192, in execute_callable
    return self.python_callable(*self.op_args, **self.op_kwargs)
[2024-10-13T19:06:30.227+0000] {logging_mixin.py:137} WARNING -   File "/opt/***/scripts/s3_db.py", line 311, in main_s3_db
    result = db_file_write(db_conn, target_db, target_table, inputs[0],load_type)
[2024-10-13T19:06:30.227+0000] {logging_mixin.py:137} WARNING -   File "/opt/***/scripts/s3_db.py", line 245, in db_file_write
    logging.info("RC:",rc)
[2024-10-13T19:06:30.227+0000] {logging_mixin.py:137} WARNING -   File "/usr/local/lib/python3.9/logging/__init__.py", line 2097, in info
    root.info(msg, *args, **kwargs)
[2024-10-13T19:06:30.227+0000] {logging_mixin.py:137} WARNING -   File "/usr/local/lib/python3.9/logging/__init__.py", line 1446, in info
    self._log(INFO, msg, args, **kwargs)
[2024-10-13T19:06:30.227+0000] {logging_mixin.py:137} WARNING -   File "/usr/local/lib/python3.9/logging/__init__.py", line 1589, in _log
    self.handle(record)
[2024-10-13T19:06:30.227+0000] {logging_mixin.py:137} WARNING -   File "/usr/local/lib/python3.9/logging/__init__.py", line 1599, in handle
    self.callHandlers(record)
[2024-10-13T19:06:30.227+0000] {logging_mixin.py:137} WARNING -   File "/usr/local/lib/python3.9/logging/__init__.py", line 1661, in callHandlers
    hdlr.handle(record)
[2024-10-13T19:06:30.227+0000] {logging_mixin.py:137} WARNING -   File "/usr/local/lib/python3.9/logging/__init__.py", line 952, in handle
    self.emit(record)
[2024-10-13T19:06:30.227+0000] {logging_mixin.py:137} WARNING -   File "/usr/local/lib/python3.9/site-packages/***/utils/log/file_task_handler.py", line 80, in emit
    self.handler.emit(record)
[2024-10-13T19:06:30.227+0000] {logging_mixin.py:137} WARNING - Message: 'RC:'
Arguments: (918,)
[2024-10-13T19:06:30.567+0000] {s3_db.py:263} INFO - Completed writing to target table.......
[2024-10-13T19:06:30.567+0000] {s3_db.py:317} INFO - Updating run_log, marking status as success........ 
[2024-10-13T19:06:30.570+0000] {s3_db.py:51} INFO - Updating run log for write operation....
[2024-10-13T19:06:30.571+0000] {s3_db.py:55} INFO - Run log updated successfully....
[2024-10-13T19:06:30.571+0000] {s3_db.py:319} INFO - 918 records transferred from s3a://sdevalla-buck/sftp_file_receiver/sftp_s3_yyyymmddHHMMSS.csv to ***.public.reddit_d
[2024-10-13T19:06:30.854+0000] {python.py:177} INFO - Done. Returned value was: 918
[2024-10-13T19:06:30.884+0000] {taskinstance.py:1327} INFO - Marking task as SUCCESS. dag_id=pipeline_Demo, task_id=S3_to_DB, execution_date=20241013T190543, start_date=20241013T190623, end_date=20241013T190630
[2024-10-13T19:06:30.948+0000] {local_task_job.py:212} INFO - Task exited with return code 0
[2024-10-13T19:06:30.974+0000] {taskinstance.py:2596} INFO - 1 downstream tasks scheduled from follow-on schedule check
