[2024-10-09T19:34:52.942+0000] {taskinstance.py:1090} INFO - Dependencies all met for dep_context=non-requeueable deps ti=<TaskInstance: pipeline_A.task_0_S3_to_DB manual__2024-10-09T19:34:13.885763+00:00 [queued]>
[2024-10-09T19:34:52.946+0000] {taskinstance.py:1090} INFO - Dependencies all met for dep_context=requeueable deps ti=<TaskInstance: pipeline_A.task_0_S3_to_DB manual__2024-10-09T19:34:13.885763+00:00 [queued]>
[2024-10-09T19:34:52.946+0000] {taskinstance.py:1288} INFO - 
--------------------------------------------------------------------------------
[2024-10-09T19:34:52.946+0000] {taskinstance.py:1289} INFO - Starting attempt 2 of 2
[2024-10-09T19:34:52.946+0000] {taskinstance.py:1290} INFO - 
--------------------------------------------------------------------------------
[2024-10-09T19:34:52.951+0000] {taskinstance.py:1309} INFO - Executing <Task(PythonOperator): task_0_S3_to_DB> on 2024-10-09 19:34:13.885763+00:00
[2024-10-09T19:34:52.956+0000] {standard_task_runner.py:55} INFO - Started process 16506 to run task
[2024-10-09T19:34:52.959+0000] {standard_task_runner.py:82} INFO - Running: ['***', 'tasks', 'run', 'pipeline_A', 'task_0_S3_to_DB', 'manual__2024-10-09T19:34:13.885763+00:00', '--job-id', '11', '--raw', '--subdir', 'DAGS_FOLDER/pipeline_A.py', '--cfg-path', '/tmp/tmp85zbxers']
[2024-10-09T19:34:52.961+0000] {standard_task_runner.py:83} INFO - Job 11: Subtask task_0_S3_to_DB
[2024-10-09T19:34:52.970+0000] {logging_mixin.py:137} WARNING - /usr/local/lib/python3.9/site-packages/***/settings.py:250 DeprecationWarning: The sql_alchemy_conn option in [core] has been moved to the sql_alchemy_conn option in [database] - the old setting has been used, but please update your config.
[2024-10-09T19:34:52.990+0000] {task_command.py:389} INFO - Running <TaskInstance: pipeline_A.task_0_S3_to_DB manual__2024-10-09T19:34:13.885763+00:00 [running]> on host e3d3232fb6c8
[2024-10-09T19:34:53.015+0000] {taskinstance.py:1516} INFO - Exporting the following env vars:
AIRFLOW_CTX_DAG_EMAIL=sdevalla@purdue.edu
AIRFLOW_CTX_DAG_OWNER=***
AIRFLOW_CTX_DAG_ID=pipeline_A
AIRFLOW_CTX_TASK_ID=task_0_S3_to_DB
AIRFLOW_CTX_EXECUTION_DATE=2024-10-09T19:34:13.885763+00:00
AIRFLOW_CTX_TRY_NUMBER=2
AIRFLOW_CTX_DAG_RUN_ID=manual__2024-10-09T19:34:13.885763+00:00
[2024-10-09T19:34:53.016+0000] {s3_db.py:97} INFO - Executing S3 File read.......
[2024-10-09T19:34:53.016+0000] {s3_db.py:18} INFO - Creating Spark session ......
[2024-10-09T19:34:55.869+0000] {taskinstance.py:1776} ERROR - Task failed with exception
Traceback (most recent call last):
  File "/usr/local/lib/python3.9/site-packages/airflow/operators/python.py", line 175, in execute
    return_value = self.execute_callable()
  File "/usr/local/lib/python3.9/site-packages/airflow/operators/python.py", line 192, in execute_callable
    return self.python_callable(*self.op_args, **self.op_kwargs)
  File "/opt/airflow/scripts/s3_db.py", line 275, in main_s3_db
    inputs = s3_file_read(s3_conn, source_s3_path, header, delimiter)
  File "/opt/airflow/scripts/s3_db.py", line 153, in s3_file_read
    df = spark.read.format(file_format).option("inferSchema", "true").option("header", header).option("delimiter",delimiter).csv(source_s3_path)
  File "/usr/local/lib/python3.9/site-packages/pyspark/sql/readwriter.py", line 727, in csv
    return self._df(self._jreader.csv(self._spark._sc._jvm.PythonUtils.toSeq(path)))
  File "/usr/local/lib/python3.9/site-packages/py4j/java_gateway.py", line 1322, in __call__
    return_value = get_return_value(
  File "/usr/local/lib/python3.9/site-packages/pyspark/errors/exceptions/captured.py", line 169, in deco
    return f(*a, **kw)
  File "/usr/local/lib/python3.9/site-packages/py4j/protocol.py", line 326, in get_return_value
    raise Py4JJavaError(
py4j.protocol.Py4JJavaError: An error occurred while calling o31.csv.
: java.lang.RuntimeException: java.lang.ClassNotFoundException: Class org.apache.hadoop.fs.s3a.S3AFileSystem not found
	at org.apache.hadoop.conf.Configuration.getClass(Configuration.java:2688)
	at org.apache.hadoop.fs.FileSystem.getFileSystemClass(FileSystem.java:3431)
	at org.apache.hadoop.fs.FileSystem.createFileSystem(FileSystem.java:3466)
	at org.apache.hadoop.fs.FileSystem.access$300(FileSystem.java:174)
	at org.apache.hadoop.fs.FileSystem$Cache.getInternal(FileSystem.java:3574)
	at org.apache.hadoop.fs.FileSystem$Cache.get(FileSystem.java:3521)
	at org.apache.hadoop.fs.FileSystem.get(FileSystem.java:540)
	at org.apache.hadoop.fs.Path.getFileSystem(Path.java:365)
	at org.apache.spark.sql.execution.datasources.DataSource$.$anonfun$checkAndGlobPathIfNecessary$1(DataSource.scala:724)
	at scala.collection.immutable.List.map(List.scala:293)
	at org.apache.spark.sql.execution.datasources.DataSource$.checkAndGlobPathIfNecessary(DataSource.scala:722)
	at org.apache.spark.sql.execution.datasources.DataSource.checkAndGlobPathIfNecessary(DataSource.scala:551)
	at org.apache.spark.sql.execution.datasources.DataSource.resolveRelation(DataSource.scala:404)
	at org.apache.spark.sql.DataFrameReader.loadV1Source(DataFrameReader.scala:229)
	at org.apache.spark.sql.DataFrameReader.$anonfun$load$2(DataFrameReader.scala:211)
	at scala.Option.getOrElse(Option.scala:189)
	at org.apache.spark.sql.DataFrameReader.load(DataFrameReader.scala:211)
	at org.apache.spark.sql.DataFrameReader.csv(DataFrameReader.scala:538)
	at java.base/jdk.internal.reflect.NativeMethodAccessorImpl.invoke0(Native Method)
	at java.base/jdk.internal.reflect.NativeMethodAccessorImpl.invoke(NativeMethodAccessorImpl.java:77)
	at java.base/jdk.internal.reflect.DelegatingMethodAccessorImpl.invoke(DelegatingMethodAccessorImpl.java:43)
	at java.base/java.lang.reflect.Method.invoke(Method.java:569)
	at py4j.reflection.MethodInvoker.invoke(MethodInvoker.java:244)
	at py4j.reflection.ReflectionEngine.invoke(ReflectionEngine.java:374)
	at py4j.Gateway.invoke(Gateway.java:282)
	at py4j.commands.AbstractCommand.invokeMethod(AbstractCommand.java:132)
	at py4j.commands.CallCommand.execute(CallCommand.java:79)
	at py4j.ClientServerConnection.waitForCommands(ClientServerConnection.java:182)
	at py4j.ClientServerConnection.run(ClientServerConnection.java:106)
	at java.base/java.lang.Thread.run(Thread.java:840)
Caused by: java.lang.ClassNotFoundException: Class org.apache.hadoop.fs.s3a.S3AFileSystem not found
	at org.apache.hadoop.conf.Configuration.getClassByName(Configuration.java:2592)
	at org.apache.hadoop.conf.Configuration.getClass(Configuration.java:2686)
	... 29 more

[2024-10-09T19:34:55.909+0000] {taskinstance.py:1327} INFO - Marking task as FAILED. dag_id=pipeline_A, task_id=task_0_S3_to_DB, execution_date=20241009T193413, start_date=20241009T193452, end_date=20241009T193455
[2024-10-09T19:34:55.927+0000] {logging_mixin.py:137} WARNING - /usr/local/lib/python3.9/site-packages/***/utils/email.py:152 RemovedInAirflow3Warning: Fetching SMTP credentials from configuration variables will be deprecated in a future release. Please set credentials using a connection instead.
[2024-10-09T19:34:55.927+0000] {configuration.py:664} WARNING - section/key [smtp/smtp_user] not found in config
[2024-10-09T19:34:55.927+0000] {email.py:268} INFO - Email alerting: attempt 1
[2024-10-09T19:34:55.932+0000] {configuration.py:664} WARNING - section/key [smtp/smtp_user] not found in config
[2024-10-09T19:34:55.932+0000] {email.py:268} INFO - Email alerting: attempt 1
[2024-10-09T19:34:55.933+0000] {taskinstance.py:1839} ERROR - Failed to send email to: ['sdevalla@purdue.edu']
Traceback (most recent call last):
  File "/usr/local/lib/python3.9/site-packages/airflow/models/taskinstance.py", line 1383, in _run_raw_task
    self._execute_task_with_callbacks(context, test_mode)
  File "/usr/local/lib/python3.9/site-packages/airflow/models/taskinstance.py", line 1529, in _execute_task_with_callbacks
    result = self._execute_task(context, task_orig)
  File "/usr/local/lib/python3.9/site-packages/airflow/models/taskinstance.py", line 1589, in _execute_task
    result = execute_callable(context=context)
  File "/usr/local/lib/python3.9/site-packages/airflow/operators/python.py", line 175, in execute
    return_value = self.execute_callable()
  File "/usr/local/lib/python3.9/site-packages/airflow/operators/python.py", line 192, in execute_callable
    return self.python_callable(*self.op_args, **self.op_kwargs)
  File "/opt/airflow/scripts/s3_db.py", line 275, in main_s3_db
    inputs = s3_file_read(s3_conn, source_s3_path, header, delimiter)
  File "/opt/airflow/scripts/s3_db.py", line 153, in s3_file_read
    df = spark.read.format(file_format).option("inferSchema", "true").option("header", header).option("delimiter",delimiter).csv(source_s3_path)
  File "/usr/local/lib/python3.9/site-packages/pyspark/sql/readwriter.py", line 727, in csv
    return self._df(self._jreader.csv(self._spark._sc._jvm.PythonUtils.toSeq(path)))
  File "/usr/local/lib/python3.9/site-packages/py4j/java_gateway.py", line 1322, in __call__
    return_value = get_return_value(
  File "/usr/local/lib/python3.9/site-packages/pyspark/errors/exceptions/captured.py", line 169, in deco
    return f(*a, **kw)
  File "/usr/local/lib/python3.9/site-packages/py4j/protocol.py", line 326, in get_return_value
    raise Py4JJavaError(
py4j.protocol.Py4JJavaError: An error occurred while calling o31.csv.
: java.lang.RuntimeException: java.lang.ClassNotFoundException: Class org.apache.hadoop.fs.s3a.S3AFileSystem not found
	at org.apache.hadoop.conf.Configuration.getClass(Configuration.java:2688)
	at org.apache.hadoop.fs.FileSystem.getFileSystemClass(FileSystem.java:3431)
	at org.apache.hadoop.fs.FileSystem.createFileSystem(FileSystem.java:3466)
	at org.apache.hadoop.fs.FileSystem.access$300(FileSystem.java:174)
	at org.apache.hadoop.fs.FileSystem$Cache.getInternal(FileSystem.java:3574)
	at org.apache.hadoop.fs.FileSystem$Cache.get(FileSystem.java:3521)
	at org.apache.hadoop.fs.FileSystem.get(FileSystem.java:540)
	at org.apache.hadoop.fs.Path.getFileSystem(Path.java:365)
	at org.apache.spark.sql.execution.datasources.DataSource$.$anonfun$checkAndGlobPathIfNecessary$1(DataSource.scala:724)
	at scala.collection.immutable.List.map(List.scala:293)
	at org.apache.spark.sql.execution.datasources.DataSource$.checkAndGlobPathIfNecessary(DataSource.scala:722)
	at org.apache.spark.sql.execution.datasources.DataSource.checkAndGlobPathIfNecessary(DataSource.scala:551)
	at org.apache.spark.sql.execution.datasources.DataSource.resolveRelation(DataSource.scala:404)
	at org.apache.spark.sql.DataFrameReader.loadV1Source(DataFrameReader.scala:229)
	at org.apache.spark.sql.DataFrameReader.$anonfun$load$2(DataFrameReader.scala:211)
	at scala.Option.getOrElse(Option.scala:189)
	at org.apache.spark.sql.DataFrameReader.load(DataFrameReader.scala:211)
	at org.apache.spark.sql.DataFrameReader.csv(DataFrameReader.scala:538)
	at java.base/jdk.internal.reflect.NativeMethodAccessorImpl.invoke0(Native Method)
	at java.base/jdk.internal.reflect.NativeMethodAccessorImpl.invoke(NativeMethodAccessorImpl.java:77)
	at java.base/jdk.internal.reflect.DelegatingMethodAccessorImpl.invoke(DelegatingMethodAccessorImpl.java:43)
	at java.base/java.lang.reflect.Method.invoke(Method.java:569)
	at py4j.reflection.MethodInvoker.invoke(MethodInvoker.java:244)
	at py4j.reflection.ReflectionEngine.invoke(ReflectionEngine.java:374)
	at py4j.Gateway.invoke(Gateway.java:282)
	at py4j.commands.AbstractCommand.invokeMethod(AbstractCommand.java:132)
	at py4j.commands.CallCommand.execute(CallCommand.java:79)
	at py4j.ClientServerConnection.waitForCommands(ClientServerConnection.java:182)
	at py4j.ClientServerConnection.run(ClientServerConnection.java:106)
	at java.base/java.lang.Thread.run(Thread.java:840)
Caused by: java.lang.ClassNotFoundException: Class org.apache.hadoop.fs.s3a.S3AFileSystem not found
	at org.apache.hadoop.conf.Configuration.getClassByName(Configuration.java:2592)
	at org.apache.hadoop.conf.Configuration.getClass(Configuration.java:2686)
	... 29 more


During handling of the above exception, another exception occurred:

Traceback (most recent call last):
  File "/usr/local/lib/python3.9/site-packages/airflow/models/taskinstance.py", line 2239, in email_alert
    send_email(task.email, subject, html_content)
  File "/usr/local/lib/python3.9/site-packages/airflow/utils/email.py", line 78, in send_email
    return backend(
  File "/usr/local/lib/python3.9/site-packages/airflow/utils/email.py", line 152, in send_email_smtp
    send_mime_email(e_from=mail_from, e_to=recipients, mime_msg=msg, conn_id=conn_id, dryrun=dryrun)
  File "/usr/local/lib/python3.9/site-packages/airflow/utils/email.py", line 270, in send_mime_email
    smtp_conn = _get_smtp_connection(smtp_host, smtp_port, smtp_timeout, smtp_ssl)
  File "/usr/local/lib/python3.9/site-packages/airflow/utils/email.py", line 317, in _get_smtp_connection
    else smtplib.SMTP(host=host, port=port, timeout=timeout)
  File "/usr/local/lib/python3.9/smtplib.py", line 255, in __init__
    (code, msg) = self.connect(host, port)
  File "/usr/local/lib/python3.9/smtplib.py", line 341, in connect
    self.sock = self._get_socket(host, port, self.timeout)
  File "/usr/local/lib/python3.9/smtplib.py", line 312, in _get_socket
    return socket.create_connection((host, port), timeout,
  File "/usr/local/lib/python3.9/socket.py", line 856, in create_connection
    raise err
  File "/usr/local/lib/python3.9/socket.py", line 844, in create_connection
    sock.connect(sa)
ConnectionRefusedError: [Errno 111] Connection refused

During handling of the above exception, another exception occurred:

Traceback (most recent call last):
  File "/usr/local/lib/python3.9/site-packages/airflow/models/taskinstance.py", line 1837, in handle_failure
    self.email_alert(error, task)
  File "/usr/local/lib/python3.9/site-packages/airflow/models/taskinstance.py", line 2241, in email_alert
    send_email(task.email, subject, html_content_err)
  File "/usr/local/lib/python3.9/site-packages/airflow/utils/email.py", line 78, in send_email
    return backend(
  File "/usr/local/lib/python3.9/site-packages/airflow/utils/email.py", line 152, in send_email_smtp
    send_mime_email(e_from=mail_from, e_to=recipients, mime_msg=msg, conn_id=conn_id, dryrun=dryrun)
  File "/usr/local/lib/python3.9/site-packages/airflow/utils/email.py", line 270, in send_mime_email
    smtp_conn = _get_smtp_connection(smtp_host, smtp_port, smtp_timeout, smtp_ssl)
  File "/usr/local/lib/python3.9/site-packages/airflow/utils/email.py", line 317, in _get_smtp_connection
    else smtplib.SMTP(host=host, port=port, timeout=timeout)
  File "/usr/local/lib/python3.9/smtplib.py", line 255, in __init__
    (code, msg) = self.connect(host, port)
  File "/usr/local/lib/python3.9/smtplib.py", line 341, in connect
    self.sock = self._get_socket(host, port, self.timeout)
  File "/usr/local/lib/python3.9/smtplib.py", line 312, in _get_socket
    return socket.create_connection((host, port), timeout,
  File "/usr/local/lib/python3.9/socket.py", line 856, in create_connection
    raise err
  File "/usr/local/lib/python3.9/socket.py", line 844, in create_connection
    sock.connect(sa)
ConnectionRefusedError: [Errno 111] Connection refused
[2024-10-09T19:34:55.943+0000] {standard_task_runner.py:100} ERROR - Failed to execute job 11 for task task_0_S3_to_DB (An error occurred while calling o31.csv.
: java.lang.RuntimeException: java.lang.ClassNotFoundException: Class org.apache.hadoop.fs.s3a.S3AFileSystem not found
	at org.apache.hadoop.conf.Configuration.getClass(Configuration.java:2688)
	at org.apache.hadoop.fs.FileSystem.getFileSystemClass(FileSystem.java:3431)
	at org.apache.hadoop.fs.FileSystem.createFileSystem(FileSystem.java:3466)
	at org.apache.hadoop.fs.FileSystem.access$300(FileSystem.java:174)
	at org.apache.hadoop.fs.FileSystem$Cache.getInternal(FileSystem.java:3574)
	at org.apache.hadoop.fs.FileSystem$Cache.get(FileSystem.java:3521)
	at org.apache.hadoop.fs.FileSystem.get(FileSystem.java:540)
	at org.apache.hadoop.fs.Path.getFileSystem(Path.java:365)
	at org.apache.spark.sql.execution.datasources.DataSource$.$anonfun$checkAndGlobPathIfNecessary$1(DataSource.scala:724)
	at scala.collection.immutable.List.map(List.scala:293)
	at org.apache.spark.sql.execution.datasources.DataSource$.checkAndGlobPathIfNecessary(DataSource.scala:722)
	at org.apache.spark.sql.execution.datasources.DataSource.checkAndGlobPathIfNecessary(DataSource.scala:551)
	at org.apache.spark.sql.execution.datasources.DataSource.resolveRelation(DataSource.scala:404)
	at org.apache.spark.sql.DataFrameReader.loadV1Source(DataFrameReader.scala:229)
	at org.apache.spark.sql.DataFrameReader.$anonfun$load$2(DataFrameReader.scala:211)
	at scala.Option.getOrElse(Option.scala:189)
	at org.apache.spark.sql.DataFrameReader.load(DataFrameReader.scala:211)
	at org.apache.spark.sql.DataFrameReader.csv(DataFrameReader.scala:538)
	at java.base/jdk.internal.reflect.NativeMethodAccessorImpl.invoke0(Native Method)
	at java.base/jdk.internal.reflect.NativeMethodAccessorImpl.invoke(NativeMethodAccessorImpl.java:77)
	at java.base/jdk.internal.reflect.DelegatingMethodAccessorImpl.invoke(DelegatingMethodAccessorImpl.java:43)
	at java.base/java.lang.reflect.Method.invoke(Method.java:569)
	at py4j.reflection.MethodInvoker.invoke(MethodInvoker.java:244)
	at py4j.reflection.ReflectionEngine.invoke(ReflectionEngine.java:374)
	at py4j.Gateway.invoke(Gateway.java:282)
	at py4j.commands.AbstractCommand.invokeMethod(AbstractCommand.java:132)
	at py4j.commands.CallCommand.execute(CallCommand.java:79)
	at py4j.ClientServerConnection.waitForCommands(ClientServerConnection.java:182)
	at py4j.ClientServerConnection.run(ClientServerConnection.java:106)
	at java.base/java.lang.Thread.run(Thread.java:840)
Caused by: java.lang.ClassNotFoundException: Class org.apache.hadoop.fs.s3a.S3AFileSystem not found
	at org.apache.hadoop.conf.Configuration.getClassByName(Configuration.java:2592)
	at org.apache.hadoop.conf.Configuration.getClass(Configuration.java:2686)
	... 29 more
; 16506)
[2024-10-09T19:34:55.987+0000] {local_task_job.py:212} INFO - Task exited with return code 1
[2024-10-09T19:34:56.012+0000] {taskinstance.py:2596} INFO - 0 downstream tasks scheduled from follow-on schedule check
