[2024-10-10T21:19:18.854+0000] {taskinstance.py:1090} INFO - Dependencies all met for dep_context=non-requeueable deps ti=<TaskInstance: pipeline_A.task_0_S3_to_DB manual__2024-10-10T21:16:54.314271+00:00 [queued]>
[2024-10-10T21:19:18.858+0000] {taskinstance.py:1090} INFO - Dependencies all met for dep_context=requeueable deps ti=<TaskInstance: pipeline_A.task_0_S3_to_DB manual__2024-10-10T21:16:54.314271+00:00 [queued]>
[2024-10-10T21:19:18.858+0000] {taskinstance.py:1288} INFO - 
--------------------------------------------------------------------------------
[2024-10-10T21:19:18.858+0000] {taskinstance.py:1289} INFO - Starting attempt 2 of 2
[2024-10-10T21:19:18.858+0000] {taskinstance.py:1290} INFO - 
--------------------------------------------------------------------------------
[2024-10-10T21:19:18.863+0000] {taskinstance.py:1309} INFO - Executing <Task(PythonOperator): task_0_S3_to_DB> on 2024-10-10 21:16:54.314271+00:00
[2024-10-10T21:19:18.870+0000] {standard_task_runner.py:55} INFO - Started process 88810 to run task
[2024-10-10T21:19:18.874+0000] {standard_task_runner.py:82} INFO - Running: ['***', 'tasks', 'run', 'pipeline_A', 'task_0_S3_to_DB', 'manual__2024-10-10T21:16:54.314271+00:00', '--job-id', '19', '--raw', '--subdir', 'DAGS_FOLDER/pipeline_A.py', '--cfg-path', '/tmp/tmp2w_nvo0g']
[2024-10-10T21:19:18.878+0000] {standard_task_runner.py:83} INFO - Job 19: Subtask task_0_S3_to_DB
[2024-10-10T21:19:18.896+0000] {logging_mixin.py:137} WARNING - /usr/local/lib/python3.9/site-packages/***/settings.py:250 DeprecationWarning: The sql_alchemy_conn option in [core] has been moved to the sql_alchemy_conn option in [database] - the old setting has been used, but please update your config.
[2024-10-10T21:19:18.926+0000] {task_command.py:389} INFO - Running <TaskInstance: pipeline_A.task_0_S3_to_DB manual__2024-10-10T21:16:54.314271+00:00 [running]> on host d6685a94b59c
[2024-10-10T21:19:18.953+0000] {taskinstance.py:1516} INFO - Exporting the following env vars:
AIRFLOW_CTX_DAG_OWNER=***
AIRFLOW_CTX_DAG_ID=pipeline_A
AIRFLOW_CTX_TASK_ID=task_0_S3_to_DB
AIRFLOW_CTX_EXECUTION_DATE=2024-10-10T21:16:54.314271+00:00
AIRFLOW_CTX_TRY_NUMBER=2
AIRFLOW_CTX_DAG_RUN_ID=manual__2024-10-10T21:16:54.314271+00:00
[2024-10-10T21:19:18.955+0000] {s3_db.py:130} INFO - Executing S3 File read.......
[2024-10-10T21:19:18.955+0000] {s3_db.py:17} INFO - Creating Spark session ......
[2024-10-10T21:19:28.857+0000] {s3_db.py:52} INFO - Updating run log for read operation....
[2024-10-10T21:19:28.862+0000] {s3_db.py:56} INFO - Run log updated successfully....
[2024-10-10T21:19:28.872+0000] {taskinstance.py:1776} ERROR - Task failed with exception
Traceback (most recent call last):
  File "/usr/local/lib/python3.9/site-packages/airflow/operators/python.py", line 175, in execute
    return_value = self.execute_callable()
  File "/usr/local/lib/python3.9/site-packages/airflow/operators/python.py", line 192, in execute_callable
    return self.python_callable(*self.op_args, **self.op_kwargs)
  File "/opt/airflow/scripts/s3_db.py", line 308, in main_s3_db
    result = db_file_write(db_conn, target_db, target_table, inputs[0],load_type, s3_access)
TypeError: db_file_write() takes 5 positional arguments but 6 were given
[2024-10-10T21:19:28.899+0000] {taskinstance.py:1327} INFO - Marking task as FAILED. dag_id=pipeline_A, task_id=task_0_S3_to_DB, execution_date=20241010T211654, start_date=20241010T211918, end_date=20241010T211928
[2024-10-10T21:19:28.914+0000] {standard_task_runner.py:100} ERROR - Failed to execute job 19 for task task_0_S3_to_DB (db_file_write() takes 5 positional arguments but 6 were given; 88810)
[2024-10-10T21:19:28.948+0000] {local_task_job.py:212} INFO - Task exited with return code 1
[2024-10-10T21:19:28.996+0000] {taskinstance.py:2596} INFO - 0 downstream tasks scheduled from follow-on schedule check
