[2024-10-11T21:32:59.153+0000] {taskinstance.py:1090} INFO - Dependencies all met for dep_context=non-requeueable deps ti=<TaskInstance: pipeline_Test_1.DB_to_S3 manual__2024-10-11T21:32:24.065285+00:00 [queued]>
[2024-10-11T21:32:59.157+0000] {taskinstance.py:1090} INFO - Dependencies all met for dep_context=requeueable deps ti=<TaskInstance: pipeline_Test_1.DB_to_S3 manual__2024-10-11T21:32:24.065285+00:00 [queued]>
[2024-10-11T21:32:59.157+0000] {taskinstance.py:1288} INFO - 
--------------------------------------------------------------------------------
[2024-10-11T21:32:59.158+0000] {taskinstance.py:1289} INFO - Starting attempt 1 of 1
[2024-10-11T21:32:59.158+0000] {taskinstance.py:1290} INFO - 
--------------------------------------------------------------------------------
[2024-10-11T21:32:59.163+0000] {taskinstance.py:1309} INFO - Executing <Task(PythonOperator): DB_to_S3> on 2024-10-11 21:32:24.065285+00:00
[2024-10-11T21:32:59.169+0000] {standard_task_runner.py:55} INFO - Started process 98927 to run task
[2024-10-11T21:32:59.171+0000] {standard_task_runner.py:82} INFO - Running: ['***', 'tasks', 'run', 'pipeline_Test_1', 'DB_to_S3', 'manual__2024-10-11T21:32:24.065285+00:00', '--job-id', '37', '--raw', '--subdir', 'DAGS_FOLDER/pipeline_Test_1.py', '--cfg-path', '/tmp/tmp6ijs4l22']
[2024-10-11T21:32:59.172+0000] {standard_task_runner.py:83} INFO - Job 37: Subtask DB_to_S3
[2024-10-11T21:32:59.185+0000] {logging_mixin.py:137} WARNING - /usr/local/lib/python3.9/site-packages/***/settings.py:250 DeprecationWarning: The sql_alchemy_conn option in [core] has been moved to the sql_alchemy_conn option in [database] - the old setting has been used, but please update your config.
[2024-10-11T21:32:59.220+0000] {task_command.py:389} INFO - Running <TaskInstance: pipeline_Test_1.DB_to_S3 manual__2024-10-11T21:32:24.065285+00:00 [running]> on host 233010463d86
[2024-10-11T21:32:59.260+0000] {taskinstance.py:1516} INFO - Exporting the following env vars:
AIRFLOW_CTX_DAG_OWNER=***
AIRFLOW_CTX_DAG_ID=pipeline_Test_1
AIRFLOW_CTX_TASK_ID=DB_to_S3
AIRFLOW_CTX_EXECUTION_DATE=2024-10-11T21:32:24.065285+00:00
AIRFLOW_CTX_TRY_NUMBER=1
AIRFLOW_CTX_DAG_RUN_ID=manual__2024-10-11T21:32:24.065285+00:00
[2024-10-11T21:32:59.262+0000] {db_s3.py:20} INFO - Creating Spark session ......
[2024-10-11T21:33:02.517+0000] {logging_mixin.py:137} INFO - Executable Query: (SELECT * FROM ***.publish.reddit_d)as query
[2024-10-11T21:33:03.128+0000] {db_s3.py:101} ERROR - Error during reading from table: An error occurred while calling o46.load.
: org.postgresql.util.PSQLException: ERROR: relation "publish.reddit_d" does not exist
  Position: 30
	at org.postgresql.core.v3.QueryExecutorImpl.receiveErrorResponse(QueryExecutorImpl.java:2552)
	at org.postgresql.core.v3.QueryExecutorImpl.processResults(QueryExecutorImpl.java:2284)
	at org.postgresql.core.v3.QueryExecutorImpl.execute(QueryExecutorImpl.java:322)
	at org.postgresql.jdbc.PgStatement.executeInternal(PgStatement.java:481)
	at org.postgresql.jdbc.PgStatement.execute(PgStatement.java:401)
	at org.postgresql.jdbc.PgPreparedStatement.executeWithFlags(PgPreparedStatement.java:164)
	at org.postgresql.jdbc.PgPreparedStatement.executeQuery(PgPreparedStatement.java:114)
	at org.apache.spark.sql.execution.datasources.jdbc.JDBCRDD$.getQueryOutputSchema(JDBCRDD.scala:68)
	at org.apache.spark.sql.execution.datasources.jdbc.JDBCRDD$.resolveTable(JDBCRDD.scala:58)
	at org.apache.spark.sql.execution.datasources.jdbc.JDBCRelation$.getSchema(JDBCRelation.scala:241)
	at org.apache.spark.sql.execution.datasources.jdbc.JdbcRelationProvider.createRelation(JdbcRelationProvider.scala:37)
	at org.apache.spark.sql.execution.datasources.DataSource.resolveRelation(DataSource.scala:346)
	at org.apache.spark.sql.DataFrameReader.loadV1Source(DataFrameReader.scala:229)
	at org.apache.spark.sql.DataFrameReader.$anonfun$load$2(DataFrameReader.scala:211)
	at scala.Option.getOrElse(Option.scala:189)
	at org.apache.spark.sql.DataFrameReader.load(DataFrameReader.scala:211)
	at org.apache.spark.sql.DataFrameReader.load(DataFrameReader.scala:172)
	at java.base/jdk.internal.reflect.NativeMethodAccessorImpl.invoke0(Native Method)
	at java.base/jdk.internal.reflect.NativeMethodAccessorImpl.invoke(NativeMethodAccessorImpl.java:77)
	at java.base/jdk.internal.reflect.DelegatingMethodAccessorImpl.invoke(DelegatingMethodAccessorImpl.java:43)
	at java.base/java.lang.reflect.Method.invoke(Method.java:569)
	at py4j.reflection.MethodInvoker.invoke(MethodInvoker.java:244)
	at py4j.reflection.ReflectionEngine.invoke(ReflectionEngine.java:374)
	at py4j.Gateway.invoke(Gateway.java:282)
	at py4j.commands.AbstractCommand.invokeMethod(AbstractCommand.java:132)
	at py4j.commands.CallCommand.execute(CallCommand.java:79)
	at py4j.ClientServerConnection.waitForCommands(ClientServerConnection.java:182)
	at py4j.ClientServerConnection.run(ClientServerConnection.java:106)
	at java.base/java.lang.Thread.run(Thread.java:840)

[2024-10-11T21:33:03.133+0000] {db_s3.py:51} INFO - Updating run log for read operation....
[2024-10-11T21:33:03.135+0000] {db_s3.py:55} INFO - Run log updated successfully....
[2024-10-11T21:33:03.135+0000] {db_s3.py:307} INFO - Failed to transfer file from S3 to Target table
[2024-10-11T21:33:03.138+0000] {db_s3.py:51} INFO - Updating run log for write operation....
[2024-10-11T21:33:03.139+0000] {db_s3.py:55} INFO - Run log updated successfully....
[2024-10-11T21:33:03.455+0000] {python.py:177} INFO - Done. Returned value was: None
[2024-10-11T21:33:03.476+0000] {taskinstance.py:1327} INFO - Marking task as SUCCESS. dag_id=pipeline_Test_1, task_id=DB_to_S3, execution_date=20241011T213224, start_date=20241011T213259, end_date=20241011T213303
[2024-10-11T21:33:03.513+0000] {local_task_job.py:212} INFO - Task exited with return code 0
[2024-10-11T21:33:03.561+0000] {taskinstance.py:2596} INFO - 0 downstream tasks scheduled from follow-on schedule check
