[2024-10-10T19:57:23.751+0000] {taskinstance.py:1090} INFO - Dependencies all met for dep_context=non-requeueable deps ti=<TaskInstance: pipeline_A.task_0_S3_to_DB manual__2024-10-10T19:57:19.378386+00:00 [queued]>
[2024-10-10T19:57:23.765+0000] {taskinstance.py:1090} INFO - Dependencies all met for dep_context=requeueable deps ti=<TaskInstance: pipeline_A.task_0_S3_to_DB manual__2024-10-10T19:57:19.378386+00:00 [queued]>
[2024-10-10T19:57:23.766+0000] {taskinstance.py:1288} INFO - 
--------------------------------------------------------------------------------
[2024-10-10T19:57:23.768+0000] {taskinstance.py:1289} INFO - Starting attempt 1 of 1
[2024-10-10T19:57:23.770+0000] {taskinstance.py:1290} INFO - 
--------------------------------------------------------------------------------
[2024-10-10T19:57:23.780+0000] {taskinstance.py:1309} INFO - Executing <Task(PythonOperator): task_0_S3_to_DB> on 2024-10-10 19:57:19.378386+00:00
[2024-10-10T19:57:23.807+0000] {standard_task_runner.py:55} INFO - Started process 50035 to run task
[2024-10-10T19:57:23.888+0000] {standard_task_runner.py:82} INFO - Running: ['***', 'tasks', 'run', 'pipeline_A', 'task_0_S3_to_DB', 'manual__2024-10-10T19:57:19.378386+00:00', '--job-id', '10', '--raw', '--subdir', 'DAGS_FOLDER/pipeline_A.py', '--cfg-path', '/tmp/tmp7a6tp5g7']
[2024-10-10T19:57:23.912+0000] {standard_task_runner.py:83} INFO - Job 10: Subtask task_0_S3_to_DB
[2024-10-10T19:57:24.003+0000] {logging_mixin.py:137} WARNING - /usr/local/lib/python3.9/site-packages/***/settings.py:250 DeprecationWarning: The sql_alchemy_conn option in [core] has been moved to the sql_alchemy_conn option in [database] - the old setting has been used, but please update your config.
[2024-10-10T19:57:24.097+0000] {task_command.py:389} INFO - Running <TaskInstance: pipeline_A.task_0_S3_to_DB manual__2024-10-10T19:57:19.378386+00:00 [running]> on host d6685a94b59c
[2024-10-10T19:57:24.162+0000] {taskinstance.py:1516} INFO - Exporting the following env vars:
AIRFLOW_CTX_DAG_OWNER=***
AIRFLOW_CTX_DAG_ID=pipeline_A
AIRFLOW_CTX_TASK_ID=task_0_S3_to_DB
AIRFLOW_CTX_EXECUTION_DATE=2024-10-10T19:57:19.378386+00:00
AIRFLOW_CTX_TRY_NUMBER=1
AIRFLOW_CTX_DAG_RUN_ID=manual__2024-10-10T19:57:19.378386+00:00
[2024-10-10T19:57:24.165+0000] {taskinstance.py:1776} ERROR - Task failed with exception
Traceback (most recent call last):
  File "/usr/local/lib/python3.9/site-packages/airflow/operators/python.py", line 175, in execute
    return_value = self.execute_callable()
  File "/usr/local/lib/python3.9/site-packages/airflow/operators/python.py", line 192, in execute_callable
    return self.python_callable(*self.op_args, **self.op_kwargs)
  File "/opt/airflow/scripts/s3_db.py", line 275, in main_s3_db
    run_logger('S3-DB', 'insert', s3_access, source_s3_path, '','','',db_access, target_table, 'started' )
TypeError: 'module' object is not callable
[2024-10-10T19:57:24.172+0000] {taskinstance.py:1327} INFO - Marking task as FAILED. dag_id=pipeline_A, task_id=task_0_S3_to_DB, execution_date=20241010T195719, start_date=20241010T195723, end_date=20241010T195724
[2024-10-10T19:57:24.179+0000] {standard_task_runner.py:100} ERROR - Failed to execute job 10 for task task_0_S3_to_DB ('module' object is not callable; 50035)
[2024-10-10T19:57:24.211+0000] {local_task_job.py:212} INFO - Task exited with return code 1
[2024-10-10T19:57:24.247+0000] {taskinstance.py:2596} INFO - 0 downstream tasks scheduled from follow-on schedule check
