[2024-10-10T03:38:39.095+0000] {taskinstance.py:1090} INFO - Dependencies all met for dep_context=non-requeueable deps ti=<TaskInstance: pipeline_B.task_0_DB_to_S3 manual__2024-10-10T03:37:22.574622+00:00 [queued]>
[2024-10-10T03:38:39.110+0000] {taskinstance.py:1090} INFO - Dependencies all met for dep_context=requeueable deps ti=<TaskInstance: pipeline_B.task_0_DB_to_S3 manual__2024-10-10T03:37:22.574622+00:00 [queued]>
[2024-10-10T03:38:39.110+0000] {taskinstance.py:1288} INFO - 
--------------------------------------------------------------------------------
[2024-10-10T03:38:39.110+0000] {taskinstance.py:1289} INFO - Starting attempt 2 of 2
[2024-10-10T03:38:39.110+0000] {taskinstance.py:1290} INFO - 
--------------------------------------------------------------------------------
[2024-10-10T03:38:39.122+0000] {taskinstance.py:1309} INFO - Executing <Task(PythonOperator): task_0_DB_to_S3> on 2024-10-10 03:37:22.574622+00:00
[2024-10-10T03:38:39.136+0000] {standard_task_runner.py:55} INFO - Started process 69030 to run task
[2024-10-10T03:38:39.167+0000] {standard_task_runner.py:82} INFO - Running: ['***', 'tasks', 'run', 'pipeline_B', 'task_0_DB_to_S3', 'manual__2024-10-10T03:37:22.574622+00:00', '--job-id', '20', '--raw', '--subdir', 'DAGS_FOLDER/pipeline_B.py', '--cfg-path', '/tmp/tmp8cr01em2']
[2024-10-10T03:38:39.188+0000] {standard_task_runner.py:83} INFO - Job 20: Subtask task_0_DB_to_S3
[2024-10-10T03:38:39.270+0000] {logging_mixin.py:137} WARNING - /usr/local/lib/python3.9/site-packages/***/settings.py:250 DeprecationWarning: The sql_alchemy_conn option in [core] has been moved to the sql_alchemy_conn option in [database] - the old setting has been used, but please update your config.
[2024-10-10T03:38:39.518+0000] {task_command.py:389} INFO - Running <TaskInstance: pipeline_B.task_0_DB_to_S3 manual__2024-10-10T03:37:22.574622+00:00 [running]> on host d7e677fa2cf4
[2024-10-10T03:38:39.629+0000] {taskinstance.py:1516} INFO - Exporting the following env vars:
AIRFLOW_CTX_DAG_OWNER=***
AIRFLOW_CTX_DAG_ID=pipeline_B
AIRFLOW_CTX_TASK_ID=task_0_DB_to_S3
AIRFLOW_CTX_EXECUTION_DATE=2024-10-10T03:37:22.574622+00:00
AIRFLOW_CTX_TRY_NUMBER=2
AIRFLOW_CTX_DAG_RUN_ID=manual__2024-10-10T03:37:22.574622+00:00
[2024-10-10T03:38:39.631+0000] {db_s3.py:20} INFO - Creating Spark session ......
[2024-10-10T03:38:48.521+0000] {logging_mixin.py:137} INFO - Executable Query: (SELECT * FROM ***.reddit_d)as query
[2024-10-10T03:38:49.104+0000] {db_s3.py:73} ERROR - Error during reading from table: An error occurred while calling o45.load.
: org.postgresql.util.PSQLException: ERROR: relation "***.reddit_d" does not exist
  Position: 30
	at org.postgresql.core.v3.QueryExecutorImpl.receiveErrorResponse(QueryExecutorImpl.java:2552)
	at org.postgresql.core.v3.QueryExecutorImpl.processResults(QueryExecutorImpl.java:2284)
	at org.postgresql.core.v3.QueryExecutorImpl.execute(QueryExecutorImpl.java:322)
	at org.postgresql.jdbc.PgStatement.executeInternal(PgStatement.java:481)
	at org.postgresql.jdbc.PgStatement.execute(PgStatement.java:401)
	at org.postgresql.jdbc.PgPreparedStatement.executeWithFlags(PgPreparedStatement.java:164)
	at org.postgresql.jdbc.PgPreparedStatement.executeQuery(PgPreparedStatement.java:114)
	at org.apache.spark.sql.execution.datasources.jdbc.JDBCRDD$.getQueryOutputSchema(JDBCRDD.scala:68)
	at org.apache.spark.sql.execution.datasources.jdbc.JDBCRDD$.resolveTable(JDBCRDD.scala:58)
	at org.apache.spark.sql.execution.datasources.jdbc.JDBCRelation$.getSchema(JDBCRelation.scala:241)
	at org.apache.spark.sql.execution.datasources.jdbc.JdbcRelationProvider.createRelation(JdbcRelationProvider.scala:37)
	at org.apache.spark.sql.execution.datasources.DataSource.resolveRelation(DataSource.scala:346)
	at org.apache.spark.sql.DataFrameReader.loadV1Source(DataFrameReader.scala:229)
	at org.apache.spark.sql.DataFrameReader.$anonfun$load$2(DataFrameReader.scala:211)
	at scala.Option.getOrElse(Option.scala:189)
	at org.apache.spark.sql.DataFrameReader.load(DataFrameReader.scala:211)
	at org.apache.spark.sql.DataFrameReader.load(DataFrameReader.scala:172)
	at java.base/jdk.internal.reflect.NativeMethodAccessorImpl.invoke0(Native Method)
	at java.base/jdk.internal.reflect.NativeMethodAccessorImpl.invoke(NativeMethodAccessorImpl.java:77)
	at java.base/jdk.internal.reflect.DelegatingMethodAccessorImpl.invoke(DelegatingMethodAccessorImpl.java:43)
	at java.base/java.lang.reflect.Method.invoke(Method.java:569)
	at py4j.reflection.MethodInvoker.invoke(MethodInvoker.java:244)
	at py4j.reflection.ReflectionEngine.invoke(ReflectionEngine.java:374)
	at py4j.Gateway.invoke(Gateway.java:282)
	at py4j.commands.AbstractCommand.invokeMethod(AbstractCommand.java:132)
	at py4j.commands.CallCommand.execute(CallCommand.java:79)
	at py4j.ClientServerConnection.waitForCommands(ClientServerConnection.java:182)
	at py4j.ClientServerConnection.run(ClientServerConnection.java:106)
	at java.base/java.lang.Thread.run(Thread.java:840)

[2024-10-10T03:38:49.107+0000] {db_s3.py:268} INFO - Failed to transfer file from S3 to Target table
[2024-10-10T03:38:49.109+0000] {python.py:177} INFO - Done. Returned value was: None
[2024-10-10T03:38:49.210+0000] {taskinstance.py:1327} INFO - Marking task as SUCCESS. dag_id=pipeline_B, task_id=task_0_DB_to_S3, execution_date=20241010T033722, start_date=20241010T033839, end_date=20241010T033849
[2024-10-10T03:38:49.354+0000] {local_task_job.py:212} INFO - Task exited with return code 0
[2024-10-10T03:38:49.395+0000] {taskinstance.py:2596} INFO - 0 downstream tasks scheduled from follow-on schedule check
